Workbook

Sheet Dashboard
A1: AIntern Business Model Dashboard (MYR) | B1: AIntern Business Model Dashboard (MYR) | C1: AIntern Business Model Dashboard (MYR) | D1: AIntern Business Model Dashboard (MYR) | E1: AIntern Business Model Dashboard (MYR) | F1: AIntern Business Model Dashboard (MYR) | G1: AIntern Business Model Dashboard (MYR) | H1: AIntern Business Model Dashboard (MYR) | I1: AIntern Business Model Dashboard (MYR) | J1: AIntern Business Model Dashboard (MYR) | K1: AIntern Business Model Dashboard (MYR)
A2: Base Case forecast. Update assumptions to refresh model outputs.
A4: KPI | B4: Year 1 | C4: Year 2 | D4: Year 3 | F4: Scenario | G4: 3-Year Revenue | H4: 3-Year EBITDA
A5: Gross revenue | B5: ='Annual Summary'!B7 -> 68901.536 | C5: ='Annual Summary'!C7 -> 502126.32 | D5: ='Annual Summary'!D7 -> 3659292.1 | F5: ="Bear" -> Bear | G5: =Scenarios!B8 -> 232197.18 | H5: =Scenarios!B9 -> 86109.295
A6: EBITDA | B6: ='Annual Summary'!B12 -> -23582.125 | C6: ='Annual Summary'!C12 -> 209939.36 | D6: ='Annual Summary'!D12 -> 2038001.2 | F6: ="Base" -> Base | G6: =Scenarios!C8 -> 4230320 | H6: =Scenarios!C9 -> 2224358.5
A7: Ending cash | B7: ='Annual Summary'!B14 -> -13582.125 | C7: ='Annual Summary'!C14 -> 196357.23 | D7: ='Annual Summary'!D14 -> 2234358.5 | F7: ="Bull" -> Bull | G7: =Scenarios!D8 -> 64875075 | H7: =Scenarios!D9 -> 62662423
A8: Ending active users | B8: ='Annual Summary'!B6 -> 941.96432 | C8: ='Annual Summary'!C6 -> 7518.227 | D8: ='Annual Summary'!D6 -> 55243.254
A9: Gross margin | B9: ='Annual Summary'!B10 -> 0.87883028 | C9: ='Annual Summary'!C10 -> 0.8639741 | D9: ='Annual Summary'!D10 -> 0.86255966
A12: Month | B12: Revenue | C12: EBITDA
A13: ="M1" -> M1 | B13: ='Monthly Model'!D20 -> 1972.5 | C13: ='Monthly Model'!D40 -> -3528.0375
A14: ="M2" -> M2 | B14: ='Monthly Model'!E20 -> 2327.55 | C14: ='Monthly Model'!E40 -> -3427.3642
A15: ="M3" -> M3 | B15: ='Monthly Model'!F20 -> 2746.509 | C15: ='Monthly Model'!F40 -> -3292.1214
A16: ="M4" -> M4 | B16: ='Monthly Model'!G20 -> 3240.8806 | C16: ='Monthly Model'!G40 -> -3115.6349
A17: ="M5" -> M5 | B17: ='Monthly Model'!H20 -> 3824.2391 | C17: ='Monthly Model'!H40 -> -2890.0146
A18: ="M6" -> M6 | B18: ='Monthly Model'!I20 -> 4512.6022 | C18: ='Monthly Model'!I40 -> -2605.9347
A19: ="M7" -> M7 | B19: ='Monthly Model'!J20 -> 5324.8706 | C19: ='Monthly Model'!J40 -> -2252.3754
A20: ="M8" -> M8 | B20: ='Monthly Model'!K20 -> 6283.3473 | C20: ='Monthly Model'!K40 -> -1816.317
A21: ="M9" -> M9 | B21: ='Monthly Model'!L20 -> 7414.3498 | C21: ='Monthly Model'!L40 -> -1282.3802
A22: ="M10" -> M10 | B22: ='Monthly Model'!M20 -> 8748.9327 | C22: ='Monthly Model'!M40 -> -632.39986
A23: ="M11" -> M11 | B23: ='Monthly Model'!N20 -> 10323.741 | C23: ='Monthly Model'!N40 -> 155.0759
A24: ="M12" -> M12 | B24: ='Monthly Model'!O20 -> 12182.014 | C24: ='Monthly Model'!O40 -> 1105.3784
A25: ="M13" -> M13 | B25: ='Monthly Model'!P20 -> 14374.776 | C25: ='Monthly Model'!P40 -> 2248.4171
A26: ="M14" -> M14 | B26: ='Monthly Model'!Q20 -> 16962.236 | C26: ='Monthly Model'!Q40 -> 3619.504
A27: ="M15" -> M15 | B27: ='Monthly Model'!R20 -> 20015.439 | C27: ='Monthly Model'!R40 -> 5260.3269
A28: ="M16" -> M16 | B28: ='Monthly Model'!S20 -> 23618.218 | C28: ='Monthly Model'!S40 -> 7220.0973
A29: ="M17" -> M17 | B29: ='Monthly Model'!T20 -> 27869.497 | C29: ='Monthly Model'!T40 -> 9556.9056
A30: ="M18" -> M18 | B30: ='Monthly Model'!U20 -> 32886.006 | C30: ='Monthly Model'!U40 -> 12339.32
A31: ="M19" -> M19 | B31: ='Monthly Model'!V20 -> 38805.487 | C31: ='Monthly Model'!V40 -> 15648.271
A32: ="M20" -> M20 | B32: ='Monthly Model'!W20 -> 45790.475 | C32: ='Monthly Model'!W40 -> 19579.283
A33: ="M21" -> M21 | B33: ='Monthly Model'!X20 -> 54032.761 | C33: ='Monthly Model'!X40 -> 24245.093
A34: ="M22" -> M22 | B34: ='Monthly Model'!Y20 -> 63758.658 | C34: ='Monthly Model'!Y40 -> 29778.759
A35: ="M23" -> M23 | B35: ='Monthly Model'!Z20 -> 75235.216 | C35: ='Monthly Model'!Z40 -> 36337.311
A36: ="M24" -> M24 | B36: ='Monthly Model'!AA20 -> 88777.555 | C36: ='Monthly Model'!AA40 -> 44106.069
A37: ="M25" -> M25 | B37: ='Monthly Model'!AB20 -> 104757.51 | C37: ='Monthly Model'!AB40 -> 53303.741
A38: ="M26" -> M26 | B38: ='Monthly Model'!AC20 -> 123613.87 | C38: ='Monthly Model'!AC40 -> 64188.424
A39: ="M27" -> M27 | B39: ='Monthly Model'!AD20 -> 145864.36 | C39: ='Monthly Model'!AD40 -> 77064.702
A40: ="M28" -> M28 | B40: ='Monthly Model'!AE20 -> 172119.95 | C40: ='Monthly Model'!AE40 -> 92292.014
A41: ="M29" -> M29 | B41: ='Monthly Model'!AF20 -> 203101.54 | C41: ='Monthly Model'!AF40 -> 110294.52
A42: ="M30" -> M30 | B42: ='Monthly Model'!AG20 -> 239659.82 | C42: ='Monthly Model'!AG40 -> 131572.78
A43: ="M31" -> M31 | B43: ='Monthly Model'!AH20 -> 282798.58 | C43: ='Monthly Model'!AH40 -> 156717.45
...

Sheet Assumptions
A1: AIntern Business Model - Assumptions (MYR) | B1: AIntern Business Model - Assumptions (MYR) | C1: AIntern Business Model - Assumptions (MYR) | D1: AIntern Business Model - Assumptions (MYR) | E1: AIntern Business Model - Assumptions (MYR) | F1: AIntern Business Model - Assumptions (MYR) | G1: AIntern Business Model - Assumptions (MYR) | H1: AIntern Business Model - Assumptions (MYR)
A2: Editable cells are blue text with yellow fill. Update these to test pricing, adoption, AI costs, and operating plan scenarios.
A4: Category | B4: Assumption | C4: Base Case | D4: Bear Case | E4: Bull Case | F4: Unit | G4: Source / Rationale | H4: Notes
A5: Model | B5: Forecast months | C5: 36 | D5: 36 | E5: 36 | F5: months | G5: Management assumption | H5: Monthly model uses 36-month forecast.
A6: Pricing | B6: 3-month internship pass | C6: 49 | D6: 39 | E6: 59 | F6: MYR/pass | G6: AIntern pricing assumption | H6: Intern-paid B2C one-time pass.
A7: Pricing | B7: 6-month internship pass | C7: 79 | D7: 69 | E7: 99 | F7: MYR/pass | G7: AIntern pricing assumption | H7: Longer internship option.
A8: Pricing | B8: Bundled AI upgrade | C8: 19 | D8: 15 | E8: 25 | F8: MYR/pass | G8: AIntern pricing assumption | H8: Optional upgrade; BYOK remains available.
A9: Mix | B9: 3-month pass mix | C9: 0.6 | D9: 0.65 | E9: 0.5 | F9: % | G9: Management assumption | H9: Remaining paid users take 6-month pass.
A10: Mix | B10: Bundled AI attach rate | C10: 0.25 | D10: 0.15 | E10: 0.35 | F10: % | G10: Management assumption | H10: Share of paid users buying bundled AI.
A11: Growth | B11: Month 1 new paid users | C11: 30 | D11: 15 | E11: 60 | F11: users | G11: Pilot launch assumption | H11: Paid users acquired in first month.
A12: Growth | B12: Monthly new paid user growth | C12: 0.18 | D12: 0.1 | E12: 0.25 | F12: % | G12: Management assumption | H12: Growth in new paid pass purchases.
A13: Growth | B13: Monthly churn / refund leakage | C13: 0.03 | D13: 0.05 | E13: 0.02 | F13: % | G13: Management assumption | H13: Applied to active paid users for conservative leakage.
A14: Marketing | B14: CAC per paid user | C14: 18 | D14: 28 | E14: 12 | F14: MYR/user | G14: Management assumption | H14: Paid acquisition blended with referrals/content.
A15: COGS | B15: Payment processing rate | C15: 0.035 | D15: 0.04 | E15: 0.03 | F15: % revenue | G15: Editable payment fee assumption | H15: Keep editable because provider fees vary.
A16: COGS | B16: Fixed payment fee | C16: 1 | D16: 1.2 | E16: 0.8 | F16: MYR/transaction | G16: Editable payment fee assumption | H16: Per paid pass transaction.
... A24: Finance | B24: Tax rate | C24: 0 | D24: 0 | E24: 0 | F24: % | G24: Pre-tax pilot simplification | H24: Set later when tax planning is ready.

Sheet Monthly Model
A1: AIntern Monthly Operating Model (MYR) | B1: AIntern Monthly Operating Model (MYR) | C1: AIntern Monthly Operating Model (MYR) | D1: AIntern Monthly Operating Model (MYR) | E1: AIntern Monthly Operating Model (MYR) | F1: AIntern Monthly Operating Model (MYR) | G1: AIntern Monthly Operating Model (MYR) | H1: AIntern Monthly Operating Model (MYR) | I1: AIntern Monthly Operating Model (MYR) | J1: AIntern Monthly Operating Model (MYR) | K1: AIntern Monthly Operating Model (MYR) | L1: AIntern Monthly Operating Model (MYR) | M1: AIntern Monthly Operating Model (MYR) | N1: AIntern Monthly Operating Model (MYR) | O1: AIntern Monthly Operating Model (MYR) | P1: AIntern Monthly Operating Model (MYR) | Q1: AIntern Monthly Operating Model (MYR) | R1: AIntern Monthly Operating Model (MYR) | S1: AIntern Monthly Operating Model (MYR) | T1: AIntern Monthly Operating Model (MYR) | U1: AIntern Monthly Operating Model (MYR) | V1: AIntern Monthly Operating Model (MYR) | W1: AIntern Monthly Operating Model (MYR) | X1: AIntern Monthly Operating Model (MYR) | Y1: AIntern Monthly Operating Model (MYR) | Z1: AIntern Monthly Operating Model (MYR) | AA1: AIntern Monthly Operating Model (MYR) | AB1: AIntern Monthly Operating Model (MYR) | AC1: AIntern Monthly Operating Model (MYR) | AD1: AIntern Monthly Operating Model (MYR) | AE1: AIntern Monthly Operating Model (MYR) | AF1: AIntern Monthly Operating Model (MYR) | AG1: AIntern Monthly Operating Model (MYR) | AH1: AIntern Monthly Operating Model (MYR) | AI1: AIntern Monthly Operating Model (MYR) | AJ1: AIntern Monthly Operating Model (MYR) | AK1: AIntern Monthly Operating Model (MYR) | AL1: AIntern Monthly Operating Model (MYR) | AM1: AIntern Monthly Operating Model (MYR) | AN1: AIntern Monthly Operating Model (MYR)
A2: Formula-driven 36-month model. Inputs link to Assumptions Base Case.
A4: Metric | B4: Unit | C4: Source / Notes | D4: M1 | E4: M2 | F4: M3 | G4: M4 | H4: M5 | I4: M6 | J4: M7 | K4: M8 | L4: M9 | M4: M10 | N4: M11 | O4: M12 | P4: M13 | Q4: M14 | R4: M15 | S4: M16 | T4: M17 | U4: M18 | V4: M19 | W4: M20 | X4: M21 | Y4: M22 | Z4: M23 | AA4: M24 | AB4: M25 | AC4: M26 | AD4: M27 | AE4: M28 | AF4: M29 | AG4: M30 | AH4: M31 | AI4: M32 | AJ4: M33 | AK4: M34 | AL4: M35 | AM4: M36
A6: Customer Funnel
A7: New paid users | B7: users | C7: Forecast from M1 users and monthly growth | D7: =Assumptions!$C$11 -> 30 | E7: =D7*(1+Assumptions!$C$12) -> 35.4 | F7: =E7*(1+Assumptions!$C$12) -> 41.772 | G7: =F7*(1+Assumptions!$C$12) -> 49.29096 | H7: =G7*(1+Assumptions!$C$12) -> 58.163333 | I7: =H7*(1+Assumptions!$C$12) -> 68.632733 | J7: =I7*(1+Assumptions!$C$12) -> 80.986625 | K7: =J7*(1+Assumptions!$C$12) -> 95.564217 | L7: =K7*(1+Assumptions!$C$12) -> 112.76578 | ... AM7: =AL7*(1+Assumptions!$C$12) -> 9839.9187
A8: Churn / refund leakage | B8: users | C8: Active users * leakage rate | D8: =0 -> 0 | E8: =D9*Assumptions!$C$13 -> 0.9 | F8: =E9*Assumptions!$C$13 -> 1.935 | G8: =F9*Assumptions!$C$13 -> 3.13011 | H8: =G9*Assumptions!$C$13 -> 4.5149355 | I8: =H9*Assumptions!$C$13 -> 6.1243874 | J8: =I9*Assumptions!$C$13 -> 7.9996378 | K8: =J9*Assumptions!$C$13 -> 10.189247 | L8: =K9*Assumptions!$C$13 -> 12.750496 | ... AM8: =AL9*Assumptions!$C$13 -> 1404.2269
A9: Ending active paid users | B9: users | C9: Prior active + new users - leakage | D9: =D7-D8 -> 30 | E9: =D9+E7-E8 -> 64.5 | F9: =E9+F7-F8 -> 104.337 | G9: =F9+G7-G8 -> 150.49785 | H9: =G9+H7-H8 -> 204.14625 | I9: =H9+I7-I8 -> 266.65459 | J9: =I9+J7-J8 -> 339.64158 | K9: =J9+K7-K8 -> 425.01655 | L9: =K9+L7-L8 -> 525.03183 | ... AM9: =AL9+AM7-AM8 -> 55243.254
A11: Pricing & Mix
A12: 3-month pass users | B12: users | C12: New users * 3-month mix | D12: =D7*Assumptions!$C$9 -> 18 | E12: =E7*Assumptions!$C$9 -> 21.24 | F12: =F7*Assumptions!$C$9 -> 25.0632 | G12: =G7*Assumptions!$C$9 -> 29.574576 | H12: =H7*Assumptions!$C$9 -> 34.898 | I12: =I7*Assumptions!$C$9 -> 41.17964 | J12: =J7*Assumptions!$C$9 -> 48.591975 | K12: =K7*Assumptions!$C$9 -> 57.33853 | ... AM12: =AM7*Assumptions!$C$9 -> 5903.9512
A13: 6-month pass users | B13: users | C13: New users * 6-month mix | D13: =D7*(1-Assumptions!$C$9) -> 12 | E13: =E7*(1-Assumptions!$C$9) -> 14.16 | F13: =F7*(1-Assumptions!$C$9) -> 16.7088 | G13: =G7*(1-Assumptions!$C$9) -> 19.716384 | H13: =H7*(1-Assumptions!$C$9) -> 23.265333 | I13: =I7*(1-Assumptions!$C$9) -> 27.453093 | J13: =J7*(1-Assumptions!$C$9) -> 32.39465 | K13: =K7*(1-Assumptions!$C$9) -> 38.225687 | ... AM13: =AM7*(1-Assumptions!$C$9) -> 3935.9675
A14: Bundled AI upgrade users | B14: users | C14: New users * AI attach rate | D14: =D7*Assumptions!$C$10 -> 7.5 | E14: =E7*Assumptions!$C$10 -> 8.85 | F14: =F7*Assumptions!$C$10 -> 10.443 | G14: =G7*Assumptions!$C$10 -> 12.32274 | H14: =H7*Assumptions!$C$10 -> 14.540833 | I14: =I7*Assumptions!$C$10 -> 17.158183 | J14: =J7*Assumptions!$C$10 -> 20.246656 | K14: =K7*Assumptions!$C$10 -> 23.891054 | ... AM14: =AM7*Assumptions!$C$10 -> 2459.9797
A16: Revenue
A17: 3-month pass revenue | B17: MYR | C17: 3-month users * price | D17: =D12*Assumptions!$C$6 -> 882 | E17: =E12*Assumptions!$C$6 -> 1040.76 | F17: =F12*Assumptions!$C$6 -> 1228.0968 | G17: =G12*Assumptions!$C$6 -> 1449.1542 | H17: =H12*Assumptions!$C$6 -> 1710.002 | I17: =I12*Assumptions!$C$6 -> 2017.8023 | J17: =J12*Assumptions!$C$6 -> 2381.0068 | K17: =K12*Assumptions!$C$6 -> 2809.588 | ... AM17: =AM12*Assumptions!$C$6 -> 289293.61
A18: 6-month pass revenue | B18: MYR | C18: 6-month users * price | D18: =D13*Assumptions!$C$7 -> 948 | E18: =E13*Assumptions!$C$7 -> 1118.64 | F18: =F13*Assumptions!$C$7 -> 1319.9952 | G18: =G13*Assumptions!$C$7 -> 1557.5943 | H18: =H13*Assumptions!$C$7 -> 1837.9613 | I18: =I13*Assumptions!$C$7 -> 2168.7944 | J18: =J13*Assumptions!$C$7 -> 2559.1773 | K18: =K13*Assumptions!$C$7 -> 3019.8293 | ... AM18: =AM13*Assumptions!$C$7 -> 310941.43
A19: Bundled AI revenue | B19: MYR | C19: AI upgrade users * upgrade price | D19: =D14*Assumptions!$C$8 -> 142.5 | E19: =E14*Assumptions!$C$8 -> 168.15 | F19: =F14*Assumptions!$C$8 -> 198.417 | G19: =G14*Assumptions!$C$8 -> 234.13206 | H19: =H14*Assumptions!$C$8 -> 276.27583 | I19: =I14*Assumptions!$C$8 -> 326.00548 | J19: =J14*Assumptions!$C$8 -> 384.68647 | K19: =K14*Assumptions!$C$8 -> 453.93003 | ... AM19: =AM14*Assumptions!$C$8 -> 46739.614
A20: Gross revenue | B20: MYR | C20: Sum of revenue lines | D20: =SUM(D17:D19) -> 1972.5 | E20: =SUM(E17:E19) -> 2327.55 | F20: =SUM(F17:F19) -> 2746.509 | G20: =SUM(G17:G19) -> 3240.8806 | H20: =SUM(H17:H19) -> 3824.2391 | I20: =SUM(I17:I19) -> 4512.6022 | J20: =SUM(J17:J19) -> 5324.8706 | K20: =SUM(K17:K19) -> 6283.3473 | ... AM20: =SUM(AM17:AM19) -> 646974.65
A22: COGS
A23: Payment processing fees | B23: MYR | C23: Gross revenue * fee rate + transactions * fixed fee | D23: =D20*Assumptions!$C$15+D7*Assumptions!$C$16 -> 99.0375 | E23: =E20*Assumptions!$C$15+E7*Assumptions!$C$16 -> 116.86425 | F23: =F20*Assumptions!$C$15+F7*Assumptions!$C$16 -> 137.89982 | G23: =G20*Assumptions!$C$15+G7*Assumptions!$C$16 -> 162.72178 | H23: =H20*Assumptions!$C$15+H7*Assumptions!$C$16 -> 192.0117 | I23: =I20*Assumptions!$C$15+I7*Assumptions!$C$16 -> 226.57381 | J23: =J20*Assumptions!$C$15+J7*Assumptions!$C$16 -> 267.35709 | K23: =K20*Assumptions!$C$15+K7*Assumptions!$C$16 -> 315.48137 | ... AM23: =AM20*Assumptions!$C$15+AM7*Assumptions!$C$16 -> 32484.032
A24: Bundled AI usage cost | B24: MYR | C24: Bundled AI users * cost/user | D24: =D14*Assumptions!$C$17 -> 37.5 | E24: =E14*Assumptions!$C$17 -> 44.25 | F24: =F14*Assumptions!$C$17 -> 52.215 | G24: =G14*Assumptions!$C$17 -> 61.6137 | H24: =H14*Assumptions!$C$17 -> 72.704166 | I24: =I14*Assumptions!$C$17 -> 85.790916 | J24: =J14*Assumptions!$C$17 -> 101.23328 | K24: =K14*Assumptions!$C$17 -> 119.45527 | ... AM24: =AM14*Assumptions!$C$17 -> 12299.898
A25: Infrastructure and email | B25: MYR | C25: Active users * infrastructure cost/user/month | D25: =D9*Assumptions!$C$18 -> 24 | E25: =E9*Assumptions!$C$18 -> 51.6 | F25: =F9*Assumptions!$C$18 -> 83.4696 | G25: =G9*Assumptions!$C$18 -> 120.39828 | H25: =H9*Assumptions!$C$18 -> 163.317 | I25: =I9*Assumptions!$C$18 -> 213.32367 | J25: =J9*Assumptions!$C$18 -> 271.71326 | K25: =K9*Assumptions!$C$18 -> 340.01324 | ... AM25: =AM9*Assumptions!$C$18 -> 44194.603
A26: Total COGS | B26: MYR | C26: Sum of COGS lines | D26: =SUM(D23:D25) -> 160.5375 | E26: =SUM(E23:E25) -> 212.71425 | F26: =SUM(F23:F25) -> 273.58442 | G26: =SUM(G23:G25) -> 344.73376 | H26: =SUM(H23:H25) -> 428.03287 | I26: =SUM(I23:I25) -> 525.6884 | J26: =SUM(J23:J25) -> 640.30364 | K26: =SUM(K23:K25) -> 774.94988 | ... AM26: =SUM(AM23:AM25) -> 88978.533
A28: Gross Profit
A29: Gross profit | B29: MYR | C29: Gross revenue - COGS | D29: =D20-D26 -> 1811.9625 | E29: =E20-E26 -> 2114.8358 | F29: =F20-F26 -> 2472.9246 | G29: =G20-G26 -> 2896.1469 | H29: =H20-H26 -> 3396.2063 | I29: =I20-I26 -> 3986.9138 | J29: =J20-J26 -> 4684.5669 | K29: =K20-K26 -> 5508.3974 | ... AM29: =AM20-AM26 -> 557996.12
A30: Gross margin | B30: % | C30: Gross profit / gross revenue | D30: =IFERROR(D29/D20,0) -> 0.91861217 | E30: =IFERROR(E29/E20,0) -> 0.90861023 | F30: =IFERROR(F29/F20,0) -> 0.90038831 | G30: =IFERROR(G29/G20,0) -> 0.8936296 | H30: =IFERROR(H29/H20,0) -> 0.88807372 | I30: =IFERROR(I29/I20,0) -> 0.88350659 | J30: =IFERROR(J29/J20,0) -> 0.87975226 | K30: =IFERROR(K29/K20,0) -> 0.87666607 | ... AM30: =IFERROR(AM29/AM20,0) -> 0.86246983
A32: Operating Expenses
A33: Team / founder compensation | B33: MYR | C33: Starting team cost with monthly ramp | D33: =Assumptions!$C$19 -> 3500 | E33: =D33*(1+Assumptions!$C$20) -> 3605 | F33: =E33*(1+Assumptions!$C$20) -> 3713.15 | G33: =F33*(1+Assumptions!$C$20) -> 3824.5445 | H33: =G33*(1+Assumptions!$C$20) -> 3939.2808 | I33: =H33*(1+Assumptions!$C$20) -> 4057.4593 | J33: =I33*(1+Assumptions!$C$20) -> 4179.183 | K33: =J33*(1+Assumptions!$C$20) -> 4304.5585 | L33: =K33*(1+Assumptions!$C$20) -> 4433.6953 | ... AM33: =AL33*(1+Assumptions!$C$20) -> 9848.5186
A34: Marketing variable CAC | B34: MYR | C34: New paid users * CAC | D34: =D7*Assumptions!$C$14 -> 540 | E34: =E7*Assumptions!$C$14 -> 637.2 | F34: =F7*Assumptions!$C$14 -> 751.896 | G34: =G7*Assumptions!$C$14 -> 887.23728 | H34: =H7*Assumptions!$C$14 -> 1046.94 | I34: =I7*Assumptions!$C$14 -> 1235.3892 | J34: =J7*Assumptions!$C$14 -> 1457.7592 | K34: =K7*Assumptions!$C$14 -> 1720.1559 | ... AM34: =AM7*Assumptions!$C$14 -> 177118.54
A35: Marketing base | B35: MYR | C35: Fixed monthly marketing budget | D35: =Assumptions!$C$22 -> 600 | E35: =Assumptions!$C$22 -> 600 | F35: =Assumptions!$C$22 -> 600 | G35: =Assumptions!$C$22 -> 600 | H35: =Assumptions!$C$22 -> 600 | I35: =Assumptions!$C$22 -> 600 | J35: =Assumptions!$C$22 -> 600 | K35: =Assumptions!$C$22 -> 600 | ... AM35: =Assumptions!$C$22 -> 600
A36: Tools, admin, legal | B36: MYR | C36: Base tools/admin/legal | D36: =Assumptions!$C$21 -> 700 | E36: =Assumptions!$C$21 -> 700 | F36: =Assumptions!$C$21 -> 700 | G36: =Assumptions!$C$21 -> 700 | H36: =Assumptions!$C$21 -> 700 | I36: =Assumptions!$C$21 -> 700 | J36: =Assumptions!$C$21 -> 700 | K36: =Assumptions!$C$21 -> 700 | ... AM36: =Assumptions!$C$21 -> 700
A37: Total Opex | B37: MYR | C37: Sum of operating expenses | D37: =SUM(D33:D36) -> 5340 | E37: =SUM(E33:E36) -> 5542.2 | F37: =SUM(F33:F36) -> 5765.046 | G37: =SUM(G33:G36) -> 6011.7818 | H37: =SUM(H33:H36) -> 6286.2208 | I37: =SUM(I33:I36) -> 6592.8484 | J37: =SUM(J33:J36) -> 6936.9423 | K37: =SUM(K33:K36) -> 7324.7144 | ... AM37: =SUM(AM33:AM36) -> 188267.06
A39: Profitability & Cash
A40: EBITDA | B40: MYR | C40: Gross profit - Opex | D40: =D29-D37 -> -3528.0375 | E40: =E29-E37 -> -3427.3642 | F40: =F29-F37 -> -3292.1214 | G40: =G29-G37 -> -3115.6349 | H40: =H29-H37 -> -2890.0146 | I40: =I29-I37 -> -2605.9347 | J40: =J29-J37 -> -2252.3754 | K40: =K29-K37 -> -1816.317 | ... AM40: =AM29-AM37 -> 369729.07
A41: Tax | B41: MYR | C41: Positive EBITDA * tax rate | D41: =MAX(0,D40*Assumptions!$C$24) -> 0 | E41: =MAX(0,E40*Assumptions!$C$24) -> 0 | F41: =MAX(0,F40*Assumptions!$C$24) -> 0 | G41: =MAX(0,G40*Assumptions!$C$24) -> 0 | H41: =MAX(0,H40*Assumptions!$C$24) -> 0 | I41: =MAX(0,I40*Assumptions!$C$24) -> 0 | J41: =MAX(0,J40*Assumptions!$C$24) -> 0 | K41: =MAX(0,K40*Assumptions!$C$24) -> 0 | ... AM41: =MAX(0,AM40*Assumptions!$C$24) -> 0
A42: Net income | B42: MYR | C42: EBITDA - tax | D42: =D40-D41 -> -3528.0375 | E42: =E40-E41 -> -3427.3642 | F42: =F40-F41 -> -3292.1214 | G42: =G40-G41 -> -3115.6349 | H42: =H40-H41 -> -2890.0146 | I42: =I40-I41 -> -2605.9347 | J42: =J40-J41 -> -2252.3754 | K42: =K40-K41 -> -1816.317 | ... AM42: =AM40-AM41 -> 369729.07
A43: Ending cash | B43: MYR | C43: Starting cash + cumulative net income | D43: =Assumptions!$C$23+D42 -> 6471.9625 | E43: =D43+E42 -> 3044.5983 | F43: =E43+F42 -> -247.52317 | G43: =F43+G42 -> -3363.1581 | H43: =G43+H42 -> -6253.1726 | I43: =H43+I42 -> -8859.1073 | J43: =I43+J42 -> -11111.483 | K43: =J43+K42 -> -12927.8 | L43: =K43+L42 -> -14210.18 | ... AM43: =AL43+AM42 -> 2234358.5

Sheet Annual Summary
A1: Annual Summary (MYR) | B1: Annual Summary (MYR) | C1: Annual Summary (MYR) | D1: Annual Summary (MYR) | E1: Annual Summary (MYR) | F1: Annual Summary (MYR) | G1: Annual Summary (MYR) | H1: Annual Summary (MYR)
A2: Yearly roll-up from the monthly model.
A4: Metric | B4: Year 1 | C4: Year 2 | D4: Year 3 | E4: 3-Year Total
A5: New paid users | B5: =SUM('Monthly Model'!D7:O7) -> 1047.9321 | C5: =SUM('Monthly Model'!P7:AA7) -> 7636.9023 | D5: =SUM('Monthly Model'!AB7:AM7) -> 55654.633 | E5: =SUM(B5:D5) -> 64339.467
A6: Ending active paid users | B6: ='Monthly Model'!O9 -> 941.96432 | C6: ='Monthly Model'!AA9 -> 7518.227 | D6: ='Monthly Model'!AM9 -> 55243.254 | E6: =D6 -> 55243.254
A7: Gross revenue | B7: =SUM('Monthly Model'!D20:O20) -> 68901.536 | C7: =SUM('Monthly Model'!P20:AA20) -> 502126.32 | D7: =SUM('Monthly Model'!AB20:AM20) -> 3659292.1 | E7: =SUM(B7:D7) -> 4230320
A8: Total COGS | B8: =SUM('Monthly Model'!D26:O26) -> 8348.7799 | C8: =SUM('Monthly Model'!P26:AA26) -> 68302.184 | D8: =SUM('Monthly Model'!AB26:AM26) -> 502934.33 | E8: =SUM(B8:D8) -> 579585.3
A9: Gross profit | B9: =SUM('Monthly Model'!D29:O29) -> 60552.756 | C9: =SUM('Monthly Model'!P29:AA29) -> 433824.14 | D9: =SUM('Monthly Model'!AB29:AM29) -> 3156357.8 | E9: =SUM(B9:D9) -> 3650734.7
A10: Gross margin | B10: =IFERROR(B9/B7,0) -> 0.87883028 | C10: =IFERROR(C9/C7,0) -> 0.8639741 | D10: =IFERROR(D9/D7,0) -> 0.86255966 | E10: =IFERROR(E9/E7,0) -> 0.86299256
A11: Total Opex | B11: =SUM('Monthly Model'!D37:O37) -> 84134.881 | C11: =SUM('Monthly Model'!P37:AA37) -> 223884.78 | D11: =SUM('Monthly Model'!AB37:AM37) -> 1118356.5 | E11: =SUM(B11:D11) -> 1426376.2
A12: EBITDA | B12: =SUM('Monthly Model'!D40:O40) -> -23582.125 | C12: =SUM('Monthly Model'!P40:AA40) -> 209939.36 | D12: =SUM('Monthly Model'!AB40:AM40) -> 2038001.2 | E12: =SUM(B12:D12) -> 2224358.5
A13: Net income | B13: =SUM('Monthly Model'!D42:O42) -> -23582.125 | C13: =SUM('Monthly Model'!P42:AA42) -> 209939.36 | D13: =SUM('Monthly Model'!AB42:AM42) -> 2038001.2 | E13: =SUM(B13:D13) -> 2224358.5
A14: Ending cash | B14: ='Monthly Model'!O43 -> -13582.125 | C14: ='Monthly Model'!AA43 -> 196357.23 | D14: ='Monthly Model'!AM43 -> 2234358.5 | E14: =D14 -> 2234358.5

Sheet Unit Economics
A1: Unit Economics | B1: Unit Economics | C1: Unit Economics | D1: Unit Economics | E1: Unit Economics | F1: Unit Economics | G1: Unit Economics | H1: Unit Economics
A2: Contribution per new paid user and payback using Base Case assumptions.
A4: Metric | B4: Formula / Basis | C4: Value | D4: Unit | E4: Interpretation
A5: Weighted average pass revenue | B5: 3M price * mix + 6M price * (1 - mix) | C5: =Assumptions!$C$6*Assumptions!$C$9+Assumptions!$C$7*(1-Assumptions!$C$9) -> 61 | D5: MYR/user | E5: Average base pass revenue before AI upgrade.
A6: AI revenue per paid user | B6: AI upgrade price * attach rate | C6: =Assumptions!$C$8*Assumptions!$C$10 -> 4.75 | D6: MYR/user | E6: Incremental revenue from bundled AI.
A7: ARPPU per new paid user | B7: Pass revenue + AI revenue | C7: =C5+C6 -> 65.75 | D7: MYR/user | E7: Blended revenue per paid user.
A8: Payment fee per paid user | B8: ARPPU * fee rate + fixed fee | C8: =C7*Assumptions!$C$15+Assumptions!$C$16 -> 3.30125 | D8: MYR/user | E8: Payment COGS estimate.
A9: AI COGS per paid user | B9: AI cost/user * attach rate | C9: =Assumptions!$C$17*Assumptions!$C$10 -> 1.25 | D9: MYR/user | E9: Weighted AI cost across all paid users.
A10: Contribution before infra | B10: ARPPU - payment - AI COGS | C10: =C7-C8-C9 -> 61.19875 | D10: MYR/user | E10: Useful for acquisition planning.
A11: CAC | B11: Assumptions base case | C11: =Assumptions!$C$14 -> 18 | D11: MYR/user | E11: Blended paid acquisition cost.
A12: Contribution after CAC | B12: Contribution before infra - CAC | C12: =C10-C11 -> 43.19875 | D12: MYR/user | E12: Must be positive for scalable B2C growth.
A13: CAC payback | B13: CAC / contribution before infra | C13: =IFERROR(C11/C10,0) -> 0.29412365 | D13: x | E13: Below 1.0x means CAC is recovered inside initial transaction.

Sheet Scenarios
A1: Scenario Summary | B1: Scenario Summary | C1: Scenario Summary | D1: Scenario Summary | E1: Scenario Summary | F1: Scenario Summary | G1: Scenario Summary | H1: Scenario Summary | I1: Scenario Summary | J1: Scenario Summary
A2: Bear, Base, and Bull cases are linked to the assumption columns.
A4: Metric | B4: Bear | C4: Base | D4: Bull | E4: Bear Formula | F4: Base Formula | G4: Bull Formula | H4: Notes
A5: Month 36 active paid users | B5: =Assumptions!$D$11*(1+Assumptions!$D$12)^35 -> 421.53655 | C5: ='Annual Summary'!D6 -> 55243.254 | D5: =Assumptions!$E$11*(1+Assumptions!$E$12)^35 -> 147911.42
A6: Year 3 revenue | B6: =(Assumptions!$D$11*(1+Assumptions!$D$12)^24)*((1+Assumptions!$D$12)^12-1)/Assumptions!$D$12*(Assumptions!$D$6*Assumptions!$D$9+Assumptions!$D$7*(1-Assumptions!$D$9)+Assumptions!$D$8*Assumptions!$D$10) -> 163501.13 | C6: ='Annual Summary'!D7 -> 3659292.1 | D6: =(Assumptions!$E$11*(1+Assumptions!$E$12)^24)*((1+Assumptions!$E$12)^12-1)/Assumptions!$E$12*(Assumptions!$E$6*Assumptions!$E$9+Assumptions!$E$7*(1-Assumptions!$E$9)+Assumptions!$E$8*Assumptions!$E$10) -> 60436507
A7: Year 3 EBITDA | B7: =B6*(1-Assumptions!$D$15)-(Assumptions!$D$19*(1+Assumptions!$D$20)^35*12+Assumptions!$D$22*12+Assumptions!$D$21*12+(Assumptions!$D$11*(1+Assumptions!$D$12)^24)*((1+Assumptions!$D$12)^12-1)/Assumptions!$D$12*Assumptions!$D$14) -> -13099.317 | C7: ='Annual Summary'!D12 -> 2038001.2 | D7: =D6*(1-Assumptions!$E$15)-(Assumptions!$E$19*(1+Assumptions!$E$20)^35*12+Assumptions!$E$22*12+Assumptions!$E$21*12+(Assumptions!$E$11*(1+Assumptions!$E$12)^24)*((1+Assumptions!$E$12)^12-1)/Assumptions!$E$12*Assumptions!$E$14) -> 49998829
A8: 3-year revenue | B8: =Assumptions!$D$11*((1+Assumptions!$D$12)^36-1)/Assumptions!$D$12*(Assumptions!$D$6*Assumptions!$D$9+Assumptions!$D$7*(1-Assumptions!$D$9)+Assumptions!$D$8*Assumptions!$D$10) -> 232197.18 | C8: ='Annual Summary'!E7 -> 4230320 | D8: =Assumptions!$E$11*((1+Assumptions!$E$12)^36-1)/Assumptions!$E$12*(Assumptions!$E$6*Assumptions!$E$9+Assumptions!$E$7*(1-Assumptions!$E$9)+Assumptions!$E$8*Assumptions!$E$10) -> 64875075
A9: 3-year EBITDA | B9: =B8*(1-Assumptions!$D$15)-(Assumptions!$D$19*36+Assumptions!$D$22*36+Assumptions!$D$21*36) -> 86109.295 | C9: ='Annual Summary'!E12 -> 2224358.5 | D9: =D8*(1-Assumptions!$E$15)-(Assumptions!$E$19*36+Assumptions!$E$22*36+Assumptions!$E$21*36) -> 62662423

Sheet Checks
A1: Model Checks | B1: Model Checks | C1: Model Checks | D1: Model Checks | E1: Model Checks | F1: Model Checks | G1: Model Checks | H1: Model Checks
A2: Status should be OK before relying on outputs.
A4: Check | B4: Actual | C4: Expected | D4: Difference | E4: Status | F4: Notes
A5: Revenue sums to components | B5: ='Annual Summary'!E7 -> 4230320 | C5: =SUM('Monthly Model'!D17:AM19) -> 4230320 | D5: =B5-C5 -> 0 | E5: =IF(ABS(D5)<1,"OK","Review") -> OK | F5: Gross revenue should equal revenue components.
A6: COGS sums to components | B6: ='Annual Summary'!E8 -> 579585.3 | C6: =SUM('Monthly Model'!D23:AM25) -> 579585.3 | D6: =B6-C6 -> 0 | E6: =IF(ABS(D6)<1,"OK","Review") -> OK | F6: COGS should equal payment, AI, and infra costs.
A7: Opex sums to components | B7: ='Annual Summary'!E11 -> 1426376.2 | C7: =SUM('Monthly Model'!D33:AM36) -> 1426376.2 | D7: =B7-C7 -> 0 | E7: =IF(ABS(D7)<1,"OK","Review") -> OK | F7: Opex should equal team, CAC, marketing base, tools/admin.
A8: Cash roll-forward | B8: ='Annual Summary'!E14 -> 2234358.5 | C8: =Assumptions!$C$23+'Annual Summary'!E13 -> 2234358.5 | D8: =B8-C8 -> 0 | E8: =IF(ABS(D8)<1,"OK","Review") -> OK | F8: Ending cash should equal starting cash plus cumulative net income.
A9: No formula errors in model status | B9: =0 -> 0 | C9: =0 -> 0 | D9: =B9-C9 -> 0 | E9: =IF(B9=0,"OK","Review") -> OK | F9: Tool-level workbook scan is also run before export.
A10: Overall model status | B10: =COUNTIF(E5:E9,"Review") -> 0 | C10: =0 -> 0 | D10: =B10-C10 -> 0 | E10: =IF(B10=0,"OK","Review") -> OK | F10: Dashboard can be used when this says OK.

Sheet Sources & Notes
A1: Sources & Notes | B1: Sources & Notes | C1: Sources & Notes | D1: Sources & Notes | E1: Sources & Notes | F1: Sources & Notes | G1: Sources & Notes | H1: Sources & Notes
A2: This workbook uses management assumptions and editable placeholders. Replace assumptions with actual pilot data when available.
A4: Item | B4: Value / Area | C4: Units | D4: Source Type | E4: Notes | F4: Owner
A5: Product model | B5: Intern-paid B2C | C5: n/a | D5: Project docs | E5: AIntern project plan: intern owns account and supervisor uses token links. | F5: Effort Studio
A6: Pricing | B6: 3M / 6M pass + AI upgrade | C6: MYR | D6: Management assumption | E6: Editable, to validate during pilot. | F6: Effort Studio
A7: COGS | B7: Payment, AI, infrastructure | C7: MYR / % | D7: Management assumption | E7: Provider fees and AI usage should be updated after pilot telemetry. | F7: Effort Studio
A8: Growth | B8: Paid users and CAC | C8: users / MYR | D8: Management assumption | E8: Start with campus pilot and referral/content assumptions. | F8: Effort Studio
A9: Tax | B9: 0% in base | C9: % | D9: Simplification | E9: Set once entity/tax treatment is confirmed. | F9: Finance
A10: Currency | B10: MYR | C10: MYR | D10: User request | E10: All money amounts are in Malaysian Ringgit. | F10: Effort Studio
A11: Model date | B11: 28 July 2026 | C11: date | D11: System date | E11: Prepared during Report Center pilot phase. | F11: Codex
A12: Security note | B12: No secrets included | C12: n/a | D12: Operating rule | E12: Do not store API keys, tokens, or passwords in workbook. | F12: All users
